<?xml version="1.0" ?>
<robot name="my_robot">

    <!--Body/Chassis of the robot-->
    <link name="base_link">
        <visual>
            <geometry>
                <cylinder length="0.02" radius="0.15"/>
            </geometry>
            <origin rpy="0 0 0" xyz="0 0 0"/>
        </visual>
        <collision>
            <geometry>
                <cylinder length="0.02" radius="0.15"/>
            </geometry>
            <origin rpy="0 0 0 " xyz="0 0 0"/>
        </collision>
    </link>

    <!--rigth_wheel-->
    <link name="right_wheel">
        <visual>
            <geometry>
                <cylinder length="0.02" radius="0.04"/>
            </geometry>
            <origin rpy="1.57 0  0 " xyz="0 0 0"/>
        </visual>
        <collision>
            <geometry>
                <cylinder length="0.02" radius="0.04"/>
            </geometry>
            <origin rpy="1.57 0 0 " xyz="0 0 0"/>
        </collision>

    </link>
    <joint name="right_wheel_joint" type="continuous">
        <parent link="base_link"/>
        <child link="right_wheel"/>
        <origin rpy="0 0 0" xyz="0.0 0.15 0.0"/>
        <axis rpy="0 0 0" xyz="0 1 0"/>
        <limit effort="100" velocity="100"/>
    </joint>

    <!--left_wheel-->
    <link name="left_wheel">
        <visual>            
            <geometry>
                <cylinder length="0.02" radius="0.04"/>
            </geometry>
            <origin rpy="1.57 0  0 " xyz="0 0 0"/>
        </visual>
        <collision>            
            <geometry>
                <cylinder length="0.02" radius="0.04"/>
            </geometry>
            <origin rpy="1.57 0 0 " xyz="0 0 0"/>
        </collision>
    </link>
    <joint name="left_wheel_joint" type="continuous">
        <parent link="base_link"/>
        <child link="left_wheel"/>
        <origin rpy="0 0 0" xyz="0.0 -0.15 0.0"/>
        <axis rpy="0 0 0" xyz="0 1 0"/>
        <limit effort="100" velocity="100"/>
    </joint>

    <!--Caster front wheel-->
    <link name="caster_front_wheel">
        <visual>
            <origin rpy="1.57 0 0" xyz="0 0.02 0"/>
            <geometry>
                <sphere radius="0.025"/>
            </geometry>
        </visual>
        <collision>
            <geometry>
                <sphere radius="0.025"/>
            </geometry>
            <origin rpy="1.57 0 0" xyz="0 0.02 0"/>
        </collision>
    </link>
    <joint name="caster_front_wheel_joint" type="fixed">
        <parent link="base_link"/>
        <child link="caster_front_wheel"/>
        <origin rpy="-1.57 0 0" xyz="0.115 0.0 0.007"/>
    </joint>

    <!--Caster back wheel-->
    <link name="caster_back_wheel">
        <visual>
            <origin rpy="1.57 0 0" xyz="0.02 0.02 0 "/>
            <geometry>
                <sphere radius="0.025"/>
            </geometry>
        </visual>
        <collision>
            <geometry>
                <sphere radius="0.025"/>
            </geometry>
            <origin rpy="1.57 0 0" xyz="0 0.02 0 "/>
        </collision>
    </link>
    <joint name="caster_back_joint" type="fixed">
        <parent link="base_link"/>
        <child link="caster_back_wheel"/>
        <origin rpy="-1.57 0 0" xyz="-0.135 0.0 0.009"/>
    </joint>
</robot>